Workbook

Sheet overview
A2: TOTAL BEES | B2: =B3+B4 -> 591
A3: Bees caught | B3: =sum(specimens!M:M) -> 431 | D3: Flower Species | E3: =IFERROR(__xludf.DUMMYFUNCTION("COUNTUNIQUE(flowers!D:D)-1"),117.0) -> 117
A4: Bees observed | B4: =sum(observations!E:E) -> 160 | D4: Bird Species | E4: =IFERROR(__xludf.DUMMYFUNCTION("COUNTUNIQUE(other!E:E)-1"),20.0) -> 20
A6: GARDEN | B6: BEES FROM SITE
A7: Clayton | B7: =sumif(specimens!H:H,A7,specimens!M:M) -> 29 | C7: CWG
A8: Luigi | B8: =sumif(specimens!H:H,A8,specimens!M:M) -> 12 | C8: LGL
A9: ELG | B9: =sumif(specimens!H:H,A9,specimens!M:M) -> 40 | C9: ELG
A10: PV | B10: =sumif(specimens!H:H,A10,specimens!M:M) -> 0 | C10: PVG
A11: Lydia | B11: =sumif(specimens!H:H,A11,specimens!M:M) -> 53 | C11: LMG
A12: Gallo | B12: =sumif(specimens!H:H,A12,specimens!M:M) -> 16 | C12: OEG
A13: Drew | B13: =sumif(specimens!H:H,A13,specimens!M:M) -> 39 | C13: DRE
A14: River | B14: =sumif(specimens!H:H,A14,specimens!M:M) -> 33 | C14: BXR
A15: Hornaday | B15: =sumif(specimens!H:H,A15,specimens!M:M) -> 16 | C15: HOR
A16: Happiness | B16: =sumif(specimens!H:H,A16,specimens!M:M) -> 47 | C16: GOH
A17: Oasis | B17: =sumif(specimens!H:H,A17,specimens!M:M) -> 28 | C17: OAS
A18: BLF | B18: =sumif(specimens!H:H,A18,specimens!M:M) -> 37 | C18: BLF
A19: Batey | B19: =sumif(specimens!H:H,A19,specimens!M:M) -> 6 | C19: BAT
A20: West123 | B20: =sumif(specimens!H:H,A20,specimens!M:M) -> 19 | C20: 123
A21: Cook | B21: =sumif(specimens!H:H,A21,specimens!M:M) -> 0 | C21: COOK
A22: Carrie | B22: =sumif(specimens!H:H,A22,specimens!M:M) -> 1 | C22: CMC

Sheet collections
A1: Site | B1: Address | C1: Method | D1: Date Collected | E1: Time 1 | F1: Time 2 | G1: Notes
A2: Drew | B2: {=xlookup(A2,addresses!A:A,addresses!B:B, "n/a")} -> 1070 E Tremont Ave, Bronx, NY | C2: net | D2: 46161 | E2: 0.38194444 | F2: 0.40277778
A3: River | B3: {=xlookup(A3,addresses!A:A,addresses!B:B, "n/a")} -> 1086 E 180th St, Bronx, NY | C3: net | D3: 46161 | E3: 0.42847222 | F3: 0.44930556
A4: Hornaday | B4: {=xlookup(A4,addresses!A:A,addresses!B:B, "n/a")} -> 851 Hornaday Pl, Bronx, NY | C4: net | D4: 46161 | E4: 0.46805556 | F4: 0.48888889
A5: Drew | B5: {=xlookup(A5,addresses!A:A,addresses!B:B, "n/a")} -> 1070 E Tremont Ave, Bronx, NY | C5: net | D5: 46161 | E5: 0.55208333 | F5: 0.57291667
A6: River | B6: {=xlookup(A6,addresses!A:A,addresses!B:B, "n/a")} -> 1086 E 180th St, Bronx, NY | C6: net | D6: 46161 | E6: 0.58333333 | F6: 0.60416667
A7: Hornaday | B7: {=xlookup(A7,addresses!A:A,addresses!B:B, "n/a")} -> 851 Hornaday Pl, Bronx, NY | C7: net | D7: 46161 | E7: 0.62083333 | F7: 0.64166667
A8: Clayton | B8: {=xlookup(A8,addresses!A:A,addresses!B:B, "n/a")} -> 303 W 126th St, New York, NY | C8: bowl | D8: 46171 | E8: 0.39236111 | F8: 0.42013889
A9: Luigi | B9: {=xlookup(A9,addresses!A:A,addresses!B:B, "n/a")} -> 227 W 115th St, New York, NY | C9: bowl | D9: 46171 | E9: 0.42013889 | F9: 0.44097222
A10: ELG | B10: {=xlookup(A10,addresses!A:A,addresses!B:B, "n/a")} -> 237 W 111th St, New York, NY | C10: bowl | D10: 46171 | E10: 0.44097222 | F10: 0.45694444
A11: Peaceful | B11: {=xlookup(A11,addresses!A:A,addresses!B:B, "n/a")} -> 52 E 117th St, New York, NY | C11: bowl | D11: 46171 | E11: 0.46180556 | F11: 0.47916667 | G11: sick baby rat. Mistaken for Tom. Several dead rats next day
A12: Lydia | B12: {=xlookup(A12,addresses!A:A,addresses!B:B, "n/a")} -> 1665 Park Ave, New York, NY | C12: bowl | D12: 46171 | E12: 0.47222222 | F12: 0.49097222 | G12: met Alicia.
A13: Gallo | B13: {=xlookup(A13,addresses!A:A,addresses!B:B, "n/a")} -> 1891 Lexington Ave, New York, NY | C13: bowl | D13: 46171 | E13: 0.48263889 | F13: 0.5 | G13: friendly cat. Lady who wanted Roses. Other woman who wanted to come in
A14: Drew | B14: {=xlookup(A14,addresses!A:A,addresses!B:B, "n/a")} -> 1070 E Tremont Ave, Bronx, NY | C14: bowl | D14: 46171 | E14: 0.64444444 | F14: 0.55902778 | G14: friendly ducks and goose family
A15: River | B15: {=xlookup(A15,addresses!A:A,addresses!B:B, "n/a")} -> 1086 E 180th St, Bronx, NY | C15: bowl | D15: 46171 | E15: 0.66666667 | F15: 0.59027778 | G15: crazy ant colony
A16: Hornaday | B16: {=xlookup(A16,addresses!A:A,addresses!B:B, "n/a")} -> 851 Hornaday Pl, Bronx, NY | C16: bowl | D16: 46171 | E16: 0.6875 | F16: 0.60416667
A17: Happiness | B17: {=xlookup(A17,addresses!A:A,addresses!B:B, "n/a")} -> 2160 Prospect Avenue | C17: bowl | D17: 46171 | E17: 0.70486111 | F17: 0.62152778 | G17: kitten and boy who wanted a flower
A18: Oasis | B18: {=xlookup(A18,addresses!A:A,addresses!B:B, "n/a")} -> 1981 Lafontaine Ave, Bronx, NY | C18: bowl | D18: 46171 | E18: 0.73263889 | F18: 0.64236111 | G18: chickens being picked off by raccoon, they say? Told to watch "The Beekeeper"
A19: Clayton | B19: {=xlookup(A19,addresses!A:A,addresses!B:B, "n/a")} -> 303 W 126th St, New York, NY | C19: net | D19: 46175 | E19: 0.375 | F19: 0.90069444 | G19: woman gawking at cherry tree. Guy peeing on sidewalk
A20: Luigi | B20: {=xlookup(A20,addresses!A:A,addresses!B:B, "n/a")} -> 227 W 115th St, New York, NY | C20: net | D20: 46175 | E20: 0.42152778 | F20: 0.94305556 | G20: saw a ground-nesting bee dig into soil in a raised bed!
A21: ELG | B21: {=xlookup(A21,addresses!A:A,addresses!B:B, "n/a")} -> 237 W 111th St, New York, NY | C21: net | D21: 46175 | E21: 0.45625 | F21: 0.48958333 | G21: talked to Meredith. Saw cute baby blue jay
A22: Clayton | B22: {=xlookup(A22,addresses!A:A,addresses!B:B, "n/a")} -> 303 W 126th St, New York, NY | C22: net | D22: 46175 | E22: 0.55555556 | F22: 0.58333333 | G22: Marva present
A23: Luigi | B23: {=xlookup(A23,addresses!A:A,addresses!B:B, "n/a")} -> 227 W 115th St, New York, NY | C23: net | D23: 46175 | E23: 0.60416667 | F23: 0.62708333
A24: ELG | B24: {=xlookup(A24,addresses!A:A,addresses!B:B, "n/a")} -> 237 W 111th St, New York, NY | C24: net | D24: 46175 | E24: 0.63819444 | F24: 0.66388889
A25: Happiness | B25: {=xlookup(A25,addresses!A:A,addresses!B:B, "n/a")} -> 2160 Prospect Avenue | C25: net | D25: 46177 | E25: 0.35833333 | F25: 0.39166667 | G25: on bus, heckled by a man for being white. "You're in the wrong neighborhood. You've got five boroughs". Black man with MAGA hat. Said that Trump was black (?) and disparaged Mamdani. Would've been frightened if he was not in a wheelchair. Experience at the garden itself was lovely. Used Google translate to help talk to members. A child, Andres, "helped me" with catching bees (but I was a good sport about it!)
A26: BLF | B26: {=xlookup(A26,addresses!A:A,addresses!B:B, "n/a")} -> 2485 Belmont Ave, Bronx, NY | C26: net | D26: 46177 | E26: 0.4125 | F26: 0.43888889 | G26: We're in! Used translate to speak with Aida. I'm free to come by whenever the garden is open.
A27: Oasis | B27: {=xlookup(A27,addresses!A:A,addresses!B:B, "n/a")} -> 1981 Lafontaine Ave, Bronx, NY | C27: net | D27: 46177 | E27: 0.45625 | F27: 0.48194444 | G27: Present for a shipment of mulch/soil (from GreenThumb?)
A28: Happiness | B28: {=xlookup(A28,addresses!A:A,addresses!B:B, "n/a")} -> 2160 Prospect Avenue | C28: net | D28: 46177 | E28: 0.51805556 | F28: 0.54166667
A29: BLF | B29: {=xlookup(A29,addresses!A:A,addresses!B:B, "n/a")} -> 2485 Belmont Ave, Bronx, NY | C29: net | D29: 46177 | E29: 0.55972222 | F29: 0.58472222
A30: Oasis | B30: {=xlookup(A30,addresses!A:A,addresses!B:B, "n/a")} -> 1981 Lafontaine Ave, Bronx, NY | C30: net | D30: 46177 | E30: 0.61111111 | F30: 0.63541667 | G30: Talked to Winston, the beekeeper.
A31: Gallo | B31: {=xlookup(A31,addresses!A:A,addresses!B:B, "n/a")} -> 1891 Lexington Ave, New York, NY | C31: net | D31: 46181 | E31: 0.39236111 | F31: 0.42013889
A32: Peaceful | B32: {=xlookup(A32,addresses!A:A,addresses!B:B, "n/a")} -> 52 E 117th St, New York, NY | C32: net | D32: 46181 | E32: 0.42291667 | F32: 0.44791667
A33: Lydia | B33: {=xlookup(A33,addresses!A:A,addresses!B:B, "n/a")} -> 1665 Park Ave, New York, NY | C33: net | D33: 46181 | E33: 0.45277778 | F33: 0.47916667 | G33: helped Alicia measure the pollinator garden
A34: Gallo | B34: {=xlookup(A34,addresses!A:A,addresses!B:B, "n/a")} -> 1891 Lexington Ave, New York, NY | C34: net | D34: 46181 | E34: 0.52430556 | F34: 0.54861111 | G34: met Eddie, a member.
A35: Peaceful | B35: {=xlookup(A35,addresses!A:A,addresses!B:B, "n/a")} -> 52 E 117th St, New York, NY | C35: net | D35: 46181 | E35: 0.55902778 | F35: 0.58333333 | G35: not a single bee- all shaded at this time
A36: Lydia | B36: {=xlookup(A36,addresses!A:A,addresses!B:B, "n/a")} -> 1665 Park Ave, New York, NY | C36: net | D36: 46181 | E36: 0.58888889 | F36: 0.6125
A37: River | B37: {=xlookup(A37,addresses!A:A,addresses!B:B, "n/a")} -> 1086 E 180th St, Bronx, NY | C37: net | D37: 46197 | E37: 0.39236111 | F37: 0.41666667 | G37: field assistant Xiaonan with me.
A38: Hornaday | B38: {=xlookup(A38,addresses!A:A,addresses!B:B, "n/a")} -> 851 Hornaday Pl, Bronx, NY | C38: net | D38: 46197 | E38: 0.43402778 | F38: 0.45972222
A39: Krystal | B39: {=xlookup(A39,addresses!A:A,addresses!B:B, "n/a")} -> 2093 Vyse Ave, Bronx, NY | C39: net | D39: 46197 | E39: 0.49305556 | F39: 0.52083333 | G39: backup plan after Drew gate was locked.
A40: River | B40: {=xlookup(A40,addresses!A:A,addresses!B:B, "n/a")} -> 1086 E 180th St, Bronx, NY | C40: net | D40: 46197 | E40: 0.54236111 | F40: 0.56666667
...

Sheet specimens
A1: No. | B1: ID | C1: Status? | D1: Tube Size | E1: Box Row | F1: Box Col | G1: Temp ID | H1: Site | I1: Date Deployed | J1: Time Deployed | K1: Date Collected | L1: Time Collected | M1: # of Bees | N1: Method | O1: Plant | P1: Description | Q1: Status | R1: Notes
A2: 1 | B2: 5-19-26-DREW-NET-AM-1 | C2: pinned | D2: small | E2: A | F2: 1 | H2: Drew | I2: n/a | J2: n/a | K2: 46161 | L2: 0.39583333 | M2: 2 | N2: net | O2: Brassica sp.
A3: 2 | B3: 5-19-26-DREW-NET-AM-2 | C3: pinned | D3: small | E3: A | F3: 2 | H3: Drew | I3: n/a | J3: n/a | K3: 46161 | L3: 0.40625 | M3: 1 | N3: net | O3: Brassica sp.
A4: 3 | B4: 5-19-26-DREW-NET-AM-3 | C4: pinned | D4: small | E4: A | F4: 3 | H4: Drew | I4: n/a | J4: n/a | K4: 46161 | L4: 0.40972222 | M4: 2 | N4: net | O4: Brassica sp.
A5: 4 | B5: 5-19-26-RIVER-NET-AM-1 | C5: pinned | D5: small | E5: A | F5: 4 | H5: River | I5: n/a | J5: n/a | K5: 46161 | L5: 0.43611111 | M5: 2 | N5: net | O5: Brassica sp.
A6: 5 | B6: 5-19-26-RIVER-NET-AM-2 | C6: pinned | D6: small | E6: A | F6: 5 | H6: River | I6: n/a | J6: n/a | K6: 46161 | L6: 0.44027778 | M6: 2 | N6: net | O6: Brassica sp.
A7: 6 | B7: 5-19-26-RIVER-NET-AM-3 | C7: pinned | D7: small | E7: A | F7: 6 | H7: River | I7: n/a | J7: n/a | K7: 46161 | L7: 0.44861111 | M7: 1 | N7: net | O7: Brassica sp.
A8: 7 | B8: 5-19-26-HORN-NET-AM-1 | D8: large | E8: A | F8: 1 | H8: Hornaday | I8: n/a | J8: n/a | K8: 46161 | L8: 0.47569444 | M8: 1 | N8: net | O8: Iris sp. | R8: doesn't fit in the small box.
A9: 8 | B9: 5-19-26-HORN-NET-AM-2 | C9: pinned | D9: small | E9: A | F9: 7 | H9: Hornaday | I9: n/a | J9: n/a | K9: 46161 | L9: 0.4875 | M9: 2 | N9: net | O9: Nepata racemosa | P9: Apis and shiny little blue thing
A10: 9 | B10: 5-19-26-DREW-NET-PM-1 | C10: pinned | D10: small | E10: A | F10: 8 | H10: Drew | I10: n/a | J10: n/a | K10: 46161 | L10: 0.56388889 | M10: 2 | N10: net | O10: Allium schoenoprasum
A11: 10 | B11: 5-19-26-DREW-NET-PM-2 | C11: pinned | D11: small | E11: A | F11: 9 | H11: Drew | I11: n/a | J11: n/a | K11: 46161 | L11: 0.56944444 | M11: 1 | N11: net | O11: Brassica sp.
A12: 11 | B12: 5-19-26-RIVER-NET-PM-1 | C12: pinned | D12: small | E12: A | F12: 10 | H12: River | I12: n/a | J12: n/a | K12: 46161 | L12: 0.59444444 | M12: 1 | N12: net | O12: Ruta gravolens | P12: medium bee
A13: 12 | B13: 5-28-26-CLAYTON-BOWL-BEE | C13: pinned | D13: small | E13: A | F13: 11 | H13: Clayton | I13: 46170 | J13: 0.39236111 | K13: 46171 | L13: 0.42013889 | M13: 2 | N13: bowl | O13: n/a
A14: 13 | B14: 5-28-26-LUIGI-BOWL-BEE | C14: pinned | D14: small | E14: A | F14: 12 | H14: Luigi | I14: 46170 | J14: 0.42013889 | K14: 46171 | L14: 0.44097222 | M14: 1 | N14: bowl | O14: n/a
A15: 14 | B15: 5-28-26-ELG-BOWL-BEE | C15: pinned | D15: small | E15: B | F15: 1 | H15: ELG | I15: 46170 | J15: 0.44097222 | K15: 46171 | L15: 0.45694444 | M15: 11 | N15: bowl | O15: n/a
A16: 15 | B16: 5-28-26-LYDIA-BOWL-BEE | C16: pinned | D16: small | E16: B | F16: 2 | H16: Lydia | I16: 46170 | J16: 0.47222222 | K16: 46171 | L16: 0.49097222 | M16: 4 | N16: bowl | O16: n/a
A17: 16 | B17: 5-28-26-GALLO-BOWL-BEE | C17: pinned | D17: small | E17: B | F17: 3 | H17: Gallo | I17: 46170 | J17: 0.48263889 | K17: 46171 | L17: 0.5 | M17: 3 | N17: bowl | O17: n/a
A18: 17 | B18: 5-28-26-DREW-BOWL-BEE | C18: pinned | D18: small | E18: B | F18: 4 | H18: Drew | I18: 46170 | J18: 0.64444444 | K18: 46171 | L18: 0.55902778 | M18: 1 | N18: bowl | O18: n/a
A19: 18 | B19: 5-28-26-HORN-BOWL-BEE | C19: pinned | D19: small | E19: B | F19: 5 | H19: Hornaday | I19: 46170 | J19: 0.6875 | K19: 46171 | L19: 0.60416667 | M19: 1 | N19: bowl | O19: n/a
A20: 19 | B20: 5-28-26-HAPPY-BOWL-BEE | C20: pinned | D20: small | E20: B | F20: 6 | H20: Happiness | I20: 46170 | J20: 0.70486111 | K20: 46171 | L20: 0.62152778 | M20: 3 | N20: bowl | O20: n/a
A21: 20 | B21: 6-2-26-CLAYTON-NET-AM-1 | C21: pinned | E21: B | F21: 7 | H21: Clayton | I21: n/a | J21: n/a | K21: 46175 | L21: 0.375 | M21: 3 | N21: net | O21: Coriandrum sativum
A22: 21 | B22: 6-2-26-CLAYTON-NET-AM-2 | C22: pinned | E22: B | F22: 8 | H22: Clayton | I22: n/a | J22: n/a | K22: 46175 | M22: 1 | N22: net | O22: Centaurea cyanus
A23: 22 | B23: 6-2-26-CLAYTON-NET-AM-3 | E23: B | F23: 9 | H23: Clayton | I23: n/a | J23: n/a | K23: 46175 | M23: 5 | N23: net | O23: Coriandrum sativum
A24: 23 | B24: 6-2-26-CLAYTON-NET-AM-4 | E24: B | F24: 10 | H24: Clayton | I24: n/a | J24: n/a | K24: 46175 | M24: 2 | N24: net | O24: Coriandrum sativum
A25: 24 | B25: 6-2-26-LUIGI-NET-AM-1 | E25: B | F25: 11 | H25: Luigi | I25: n/a | J25: n/a | K25: 46175 | L25: 0.42152778 | M25: 1 | N25: net | O25: Rosa sp.
A26: 25 | B26: 6-2-26-ELG-AM-2 | E26: B | F26: 12 | H26: ELG | I26: n/a | J26: n/a | K26: 46175 | M26: 1 | N26: net | O26: Rubus occidentalis | P26: ELG-AM-1 skipped by mistake
A27: 26 | B27: 6-2-26-ELG-AM-3 | E27: C | F27: 1 | H27: ELG | I27: n/a | J27: n/a | K27: 46175 | M27: 2 | N27: net | O27: Brassica rapa
A28: 27 | B28: 6-2-26-ELG-AM-4 | E28: C | F28: 2 | H28: ELG | I28: n/a | J28: n/a | K28: 46175 | M28: 3 | N28: net | O28: Brassica sp.
A29: 28 | B29: 6-2-26-ELG-AM-5 | E29: C | F29: 3 | H29: ELG | I29: n/a | J29: n/a | K29: 46175 | M29: 2 | N29: net | O29: Allium giganteum
A30: 29 | B30: 6-2-26-ELG-AM-6 | E30: C | F30: 4 | H30: ELG | I30: n/a | J30: n/a | K30: 46175 | M30: 2 | N30: net | O30: Rubus occidentalis
A31: 30 | B31: 6-2-26-CLAYTON-NET-PM-1 | E31: C | F31: 5 | H31: Clayon | I31: n/a | J31: n/a | K31: 46175 | L31: 0.55555556 | M31: 2 | N31: net | O31: Centaurea cyanus
A32: 31 | B32: 6-2-26-CLAYTON-NET-PM-2 | E32: C | F32: 6 | H32: Clayon | I32: n/a | J32: n/a | K32: 46175 | M32: 3 | N32: net | O32: Hydrangea arborescens
A33: 32 | B33: 6-2-26-CLAYTON-NET-PM-3 | E33: C | F33: 7 | H33: Clayton | I33: n/a | J33: n/a | K33: 46175 | M33: 5 | N33: net | O33: Coriandrum sativum
A34: 33 | B34: 6-2-26-CLAYTON-NET-PM-4 | E34: C | F34: 8 | H34: Clayton | I34: n/a | J34: n/a | K34: 46175 | M34: 2 | N34: net | O34: Thymus sp.
A35: 34 | B35: 6-2-26-CLAYTON-NET-PM-5 | E35: C | F35: 9 | H35: Clayton | I35: n/a | J35: n/a | K35: 46175 | M35: 1 | N35: net | O35: Solanum dulcamara
A36: 35 | B36: 6-2-26-LUIGI-NET-PM-1 | E36: C | F36: 10 | H36: Luigi | I36: n/a | J36: n/a | K36: 46175 | L36: 0.60416667 | M36: 1 | N36: net | O36: Rosa sp.
A37: 36 | B37: 6-2-26-LUIGI-NET-PM-2 | E37: C | F37: 11 | H37: Luigi | I37: n/a | J37: n/a | K37: 46175 | L37: 0.60416667 | M37: 1 | N37: net | O37: Chenopodium album | P37: on leaf. Plant not flowering
A38: 37 | B38: 6-2-26-LUIGI-NET-PM-3 | E38: C | F38: 12 | H38: Luigi | I38: n/a | J38: n/a | K38: 46175 | L38: 0.60416667 | M38: 1 | N38: net | O38: Cucumis sativus | P38: on leaf. Plant not flowering
A39: 38 | B39: 6-2-26-ELG-NET-PM-1 | E39: D | F39: 1 | H39: ELG | I39: n/a | J39: n/a | K39: 46175 | L39: 0.63819444 | M39: 2 | N39: net | O39: Rubus occidentalis
A40: 39 | B40: 6-2-26-ELG-NET-PM-2 | E40: D | F40: 2 | H40: ELG | I40: n/a | J40: n/a | K40: 46175 | M40: 2 | N40: net | O40: Brassica rapa
...

Sheet observations
A1: Site | B1: Date | C1: Time | D1: Species | E1: Quantity | F1: Plant | G1: Notes
A2: River | B2: 46160 | C2: 0.42152778 | D2: Xylocopa virginica | E2: 1 | F2: n/a | G2: around gazebo
A3: River | B3: 46160 | C3: 0.42152778 | D3: Apis Melifera | E3: 4 | F3: Brassica rapa
A4: Hornaday | B4: 46160 | C4: 0.46805556 | D4: Xylocopa virginica | E4: 4 | F4: n/a | G4: around shack
A5: Luigi | B5: 46175 | C5: 0.42152778 | D5: Xylocopa virginica | E5: 1 | F5: n/a | G5: around gazebo
A6: Clayton | C6: 0.55555556 | D6: Xylocopa virginica | E6: 2 | F6: n/a
D7: Xylocopa virginica | E7: 1 | F7: Ligustrum ovalifolium
D8: Apis Melifera | E8: 2 | F8: n/a
D9: Apis Melifera | E9: 2 | F9: Centaurea cyanus
A10: Happiness | B10: 46177 | C10: 0.35833333 | D10: Xylocopa virginica | E10: 2 | F10: n/a | G10: one shed
D11: Apis Melifera | E11: 1 | F11: Trifolium repens
D12: Apis Melifera | E12: 1 | F12: Taraxacum officinale
A13: BLF | B13: 46177 | C13: 0.4125 | D13: Apis Melifera | E13: 8 | F13: n/a | G13: in wheelbarrow filled with dirt. Can their hive be in dirt?
D14: Xylocopa virginica | E14: 1 | F14: Rosa sp. (pink)
A15: Oasis | B15: 46177 | C15: 0.45625 | D15: Xylocopa virginica | E15: 6 | F15: n/a | G15: gazebo
A16: Happiness | B16: 46177 | C16: 0.51805556 | D16: Apis Melifera | E16: 1 | F16: Rubus sp.
D17: Apis Melifera | E17: 1 | F17: Trifolium repens
A18: BLF | B18: 46177 | C18: 0.55972222 | D18: Apis Melifera | E18: 3 | F18: Rubus sp.
D19: Apis Melifera | E19: 1 | F19: Rosa sp. (white
A20: Oasis | B20: 46177 | C20: 0.61111111 | D20: Xylocopa virginica | E20: 5 | F20: n/a | G20: gazebo
D21: Apis Melifera | E21: 1 | F21: Rosa sp. (pink)
A22: Lydia | B22: 46181 | C22: 0.45277778 | D22: Apis Melifera | E22: 1 | F22: rubus allegheniensis
D23: Xylocopa virginica | E23: 1 | F23: rubus allegheniensis
A24: Lydia | B24: 46181 | C24: 0.58888889 | D24: Apis Melifera | E24: 1 | F24: rubus allegheniensis
A25: River | B25: 46197 | C25: 0.39236111 | D25: Xylocopa virginica | E25: 4 | F25: n/a
D26: Apis Melifera | E26: 1 | F26: red clover
D27: Apis Melifera | E27: 3 | F27: common lavender
D28: Xylocopa virginica | E28: 1 | F28: brassica sp.
D29: Apis Melifera | E29: 2 | F29: coriander
A30: Krystal | B30: 46197 | C30: 0.49305556 | D30: Apis Melifera | E30: 1 | F30: mophead hydrangea
A31: River | B31: 46197 | C31: 0.54166667 | D31: Bombus griseocolis | E31: 1 | F31: common lavender
D32: Bombus fervidus | E32: 1 | F32: common lavender
D33: Bombus griseocolis | E33: 1 | F33: dense blazing star
A34: Hornaday | B34: 46197 | C34: 0.59027778 | D34: Apis Melifera | E34: 1 | F34: tomato
A35: Krystal | B35: 46197 | C35: 0.61666667 | D35: Apis Melifera | E35: 1 | F35: n/a | G35: on my water bottle
A36: Batey | B36: 46198 | C36: 0.34375 | D36: Apis melifera | E36: 1 | F36: white clover
A37: Oasis | B37: 46198 | C37: 0.37152778 | D37: Apis melifera | E37: 1 | F37: hosta sp. (scented hosta?)
D38: Apis melifera | E38: 1 | F38: tomatillo
D39: Apis melifera | E39: 1 | F39: brassica sp.
D40: Xylocopa virginica | E40: 2 | F40: n/a | G40: gazebo
...

Sheet flowers
A1: Garden | B1: Date | C1: Label | D1: Scientific Name | E1: Common Name | F1: Square Area (m2) | G1: height (m) | H1: Description | I1: Notes | J1: iNat
A2: Drew Gardens | B2: 46161 | C2: A | D2: Brassica sp. | F2: 1.895 | J2: https://www.inaturalist.org/observations/363392961
C3: B | D3: Fragaria vesca | E3: wild strawberry | F3: 0.125 | J3: https://www.inaturalist.org/observations/363392737
C4: C | D4: Erigeron sp. | E4: Fleabane genus | F4: 0.045 | J4: https://www.inaturalist.org/observations/363392766
C5: D | D5: Allium schoenoprasum | E5: chives | F5: 0.3675 | J5: https://www.inaturalist.org/observations/363393967
C6: E | D6: Rosa sp. | E6: Rose genus | F6: 3.36 | J6: https://www.inaturalist.org/observations/363392798
C7: F | D7: Lonicera sp. | E7: Honeysuckle genus | F7: 0.4 | J7: https://www.inaturalist.org/observations/363392826
C8: G | E8: ?? | F8: 0.115 | J8: https://www.inaturalist.org/observations/363392854
A9: Hornaday Garden | B9: 46161 | C9: A | D9: Rosa sp. | E9: rose | F9: 0.7 | H9: bright pink, rose-like | J9: https://www.inaturalist.org/observations/363392570
C10: B | D10: Oxalis sp. | F10: > 1 | J10: https://www.inaturalist.org/observations/363392591
C11: C | D11: Aegopodium podagraria | E11: goutweed | F11: > 1 | J11: https://www.inaturalist.org/observations/363392591
C12: D | D12: Nepata racemosa | E12: eastern cat-mint | F12: 0.8
C13: E | D13: Begonia sp. | F13: 0.25 | J13: https://www.inaturalist.org/observations/363392630
C14: F | D14: Iris sp. | F14: 1.62 | J14: https://www.inaturalist.org/observations/363392675
A15: River | B15: 46161 | C15: A | D15: Lonicera sempervirens | E15: coral honeysuckle | F15: 1.8
C16: B | D16: Brassica sp. | E16: brassica | F16: 1.19 | J16: https://www.inaturalist.org/observations/363392961
C17: C | D17: Trifolium pratense | E17: red clover | F17: 2.1383 | J17: https://www.inaturalist.org/observations/363392940
C18: D | D18: Salvia sp. | E18: sage | F18: 2.7039 | J18: https://www.inaturalist.org/observations/363392988
C19: E | D19: Thymus sp. | E19: thyme | F19: 1.1928 | J19: https://www.inaturalist.org/observations/363393012
C20: F | D20: Coriandrum sativum | E20: cilantro | F20: 2.0565 | J20: https://www.inaturalist.org/observations/363392907
C21: G | D21: Erigeron annus | E21: Annual fleabane | F21: 0.0891
C22: H | D22: Ruta gravolens | E22: rue | F22: 0.48 | J22: https://www.inaturalist.org/observations/363392877
C23: I | D23: Rose sp. | E23: rose | F23: 4.32 | H23: pink rose | J23: https://www.inaturalist.org/observations/363393076
C24: J | D24: Rose sp. | E24: ? | F24: 2.25 | H24: orange rose | J24: https://www.inaturalist.org/observations/367433283
C25: K | D25: Anthemis arvensis | E25: Corn Chamomile | F25: 0.9025 | H25: a daisy? | J25: https://www.inaturalist.org/observations/363393114
C26: L | D26: Allium schoenoprasum | E26: chives | F26: 0.06
C27: M | D27: Rosa sp. | E27: rose | F27: 0.025 | H27: red rose | J27: https://www.inaturalist.org/observations/363393169
C28: N | D28: Dianthus barbatus | E28: Sweet William | F28: 0.2205 | J28: https://www.inaturalist.org/observations/363393145
C29: O | D29: Centaurea cyanus | E29: Cornflower | F29: 0.3478 | J29: https://www.inaturalist.org/observations/363393037
A30: ELG | B30: 46175 | C30: A | D30: Rubus occidentalis | E30: black raspberry | F30: =1.3*8 -> 10.4
C31: B | D31: Tagetes erecta | E31: Mexican marigold | F31: =0.1*0.1*35 -> 0.35 | J31: https://www.inaturalist.org/observations/367850694
C32: C | D32: Brassica rapa | E32: field mustard | F32: =0.35*0.65 -> 0.2275 | J32: https://www.inaturalist.org/observations/367850643
C33: D | D33: Allium giganteum | E33: giant allium | F33: =0.25*0.25 -> 0.0625
C34: E | D34: Rosa sp. | F34: =1.5*1.4+4 -> 6.1
C35: F | D35: Impatiens walleriana | E35: Busy Lizzie | F35: =0.1*0.1*22 -> 0.22 | J35: https://www.inaturalist.org/observations/367850500
C36: G | D36: Antirrhinum majus | E36: snapdragon | F36: =0.25*0.25*2 -> 0.125 | J36: https://www.inaturalist.org/observations/367850541
C37: H | D37: Brassica sp. | F37: =0.7*0.3 -> 0.21 | J37: https://www.inaturalist.org/observations/367850776
C38: I | D38: Salvia officinalis | E38: garden sage | F38: =1.1*0.5+0.1*0.2 -> 0.57 | J38: https://www.inaturalist.org/observations/367850824
C39: J | D39: Petunia integrifolia | E39: violetflower petunia | F39: =0.55*0.2 -> 0.11 | J39: https://www.inaturalist.org/observations/367850855
C40: K | D40: Allium schoenoprasum | E40: chives | F40: =0.25*0.25*2 -> 0.125 | J40: https://www.inaturalist.org/observations/367850907
...

Sheet other
A1: Site | B1: Date | C1: Time | D1: Num Species | E1: Species | F1: Count | G1: Notes | H1: Outside Count Species?
A2: Drew Gardens | B2: 46161 | C2: 0.38194444 | D2: 9 | E2: Mallard | F2: 1 | H2: GRCA, DOWO, MODO
E3: House Sparrow | F3: 4
E4: European Starling | F4: 2
E5: Northern Cardinal | F5: 1 | G5: feeding
E6: Song Sparrow | F6: 1 | G6: heard
E7: Barn Swallow | F7: 2
E8: Rock Pigeon | F8: 3
E9: American Robin | F9: 1
E10: Chimney Swift | F10: 3
A11: River Garden | B11: 46161 | C11: 0.42152778 | D11: 8 | E11: House Sparrow | F11: 6 | H11: CEDW, ROPI, BAOR, CAGO
E12: Song Sparrow | F12: 2
E13: European Starling | F13: 6
E14: Barn Swallow | F14: 2 | G14: heard
E15: Northern Cardinal | F15: 1
E16: Northern Mockingbird | F16: 1
E17: American Crow | F17: 1
E18: American Robin | F18: 1
A19: Hornaday Garden | B19: 46161 | C19: 0.46458333 | D19: 4 | E19: House Sparow | F19: 4 | G19: feeding, bathing | H19: AMRO
E20: European Starling | F20: 3 | H20: CORA
E21: Chimney Swift | F21: 3 | H21: CEDW?
E22: Rock Pigeon | F22: 1 | G22: bathed after count
A23: Clayon | B23: 46175 | C23: 0.36944444 | E23: House Sparrow | F23: 6
E24: Northern Cardinal | F24: 2 | G24: male/female pair
E25: House Finch | F25: 1 | G25: heard
E26: Chimney Swift | F26: 2
E27: European Starling | F27: 1
E28: Rock Pigeon | F28: 5
E29: Mourning Dove | F29: 1
A30: Luigi | B30: 46175 | C30: 0.41805556 | E30: House Sparrow | F30: 1 | H30: NOCA
E31: European Starling | F31: 5 | G31: fighting/ courtship | H31: MODO
E32: American Robin | F32: 2
A33: ELG | B33: 46175 | C33: 0.45 | E33: House Sparrow | F33: 4 | G33: fledgling and parent | I33: member Meredith told me she's seen goldfinches, purple finches (maybe meant HOFI), and fledgling robins and cardinals.
E34: Blue Jay | F34: 2 | G34: fledgling and parent
E35: Mourning Dove | F35: 2
E36: Chimney Swift | F36: 1 | G36: heard
E37: American Robin | F37: 1
E38: Northern Cardinal | F38: 1
E39: European Starling | F39: 1
A40: Happiness | B40: 46177 | C40: 0.35486111 | E40: Cedar Waxing | F40: 6 | H40: BLJA
...

Sheet flower key
A1: Common | B1: Scientific
A2: cucumber | B2: Cucumis sativus
A3: shaggy soldier | B3: Galinsoga quadriradiata
A4: asiatic dayflower | B4: Commelina communis
A5: tomato | B5: Solanum lycopersicum
A6: yellow woodsorrel | B6: Oxalis stricta
A7: pumpkin | B7: Cucurbita pepo
A8: mophead hydrangea | B8: Hydrangea macrophylla
A9: mexican marigold | B9: Tagetes lemmonii
A10: coriander | B10: Coriandrum sativum
A11: common hibiscus | B11: Hibiscus syriacus
A12: low smartweed | B12: Persicaria longiseta
... A39: black-eyed susan | B39: Rudbeckia hirta
A40: garden parsley
A41: bittersweet nightshade
A42: tomatillo
A43: bok choy (brassica)
A44: sweet basil
A45: chili pepper
A46: coral honeysuckle
A47: common sunflower
A48: pot marigold
A49: yellow daylily
A50: cornflower
A51: oakleaf hydrangea
... A80: large-flowered tomatillo

Sheet addresses
A1: Site | B1: Address
A2: BLF | B2: 2485 Belmont Ave, Bronx, NY
A3: Oasis | B3: 1981 Lafontaine Ave, Bronx, NY
A4: River | B4: 1086 E 180th St, Bronx, NY
A5: Happiness | B5: 2160 Prospect Avenue
A6: Drew | B6: 1070 E Tremont Ave, Bronx, NY
A7: Hornaday | B7: 851 Hornaday Pl, Bronx, NY
A8: Batey | B8: 504 E 178th St, Bronx, NY
A9: Krystal | B9: 2093 Vyse Ave, Bronx, NY
A10: Clayton | B10: 303 W 126th St, New York, NY
A11: Peaceful | B11: 52 E 117th St, New York, NY
A12: Gallo | B12: 1891 Lexington Ave, New York, NY
... A17: Lydia | B17: 1665 Park Ave, New York, NY
